<?xml version="1.0"?>
<robot name="aubo_i5" xmlns:xacro="http://ros.org/wiki/xacro">

 <!-- Defining the colors used in this robot -->
    <material name="Black">
        <color rgba="0 0 0 1"/>
    </material>

    <material name="White">
        <color rgba="1 1 1 1"/>
    </material>

    <material name="Blue">
        <color rgba="0 0 1 1"/>
    </material>

    <material name="Red">
        <color rgba="1 0 0 1"/>
    </material>

    <material name="Grey">
        <color rgba="0.96 0.96 0.96 1"/>
    </material>

    <!-- Constants -->
    <xacro:property name="M_PI" value="3.14159"/>







    <!--/////////////////// DYNAMICS PARAM //////////////////////-->

    <xacro:macro name="I5_Shoulder_Inertia">
        <origin xyz="0.0 0.006 -0.002"
                rpy="0 0 0" />
        <mass value="5.05" />
        <inertia ixx="0.0148"
                 ixy="0"
                 ixz="0"
                 iyy="0.0143"
                 iyz="-0.0"
                 izz="0.0095" />
    </xacro:macro>

    <xacro:macro name="I5_UpperArm_Inertia">
        <origin xyz="0.304 0.0 -0.03"
                rpy="0 0 0" />
        <mass value="11.90" />
        <inertia ixx="0.0305"
                 ixy="0"
                 ixz="0"
                 iyy="0.4505"
                 iyz="0"
                 izz="0.0095" />
    </xacro:macro>

    <xacro:macro name="I5_ForeArm_Inertia">
        <origin xyz="0.415 0.0 0.0992"
                rpy="0 0 0" />
        <mass  value="3.3" />
        <inertia ixx="0.0033"
                 ixy="0"
                 ixz="0.0009"
                 iyy="0.0575"
                 iyz="0"
                 izz="0.0565" />
    </xacro:macro>

    <xacro:macro name="I5_Wrist1_Inertia">
        <origin xyz="0.0 0.0028 -0.003"
                rpy="0 0 0" />
        <mass value="1.62" />
        <inertia ixx="0.0023"
                 ixy="0"
                 ixz="0"
                 iyy="0.0013"
                 iyz="0.0"
                 izz="0.0022" />
    </xacro:macro>

    <xacro:macro name="I5_Wrist2_Inertia">
        <origin xyz="0.0 -0.0028 -0.003"
                rpy="0 0 0" />
        <mass value="1.62" />
        <inertia ixx="0.0023"
                 ixy="0"
                 ixz="0"
                 iyy="0.0013"
                 iyz="0.0"
                 izz="0.0022" />
    </xacro:macro>

    <xacro:macro name="I5_Wrist3_Inertia">
        <origin xyz="0.0 0.0 -0.0071"
                rpy="0 0 0" />
        <mass value="0.40" />
        <inertia ixx="0.013939"
                 ixy="0"
                 ixz="0"
                 iyy="0.013988"
                 iyz="0.0"
                 izz="0.0224092" />
    </xacro:macro>









    <!--/////////////////////////////// BASE_LINK ////////////////////////////////////-->
   
   <link name="base_link">
    <inertial>
      <origin xyz="-1.4795E-13 0.0015384 0.020951" rpy="0 0 0" />
      <mass value="0.83419" />
      <inertia ixx="0.0014414" ixy="7.8809E-15" ixz="8.5328E-16" iyy="0.0013542" iyz="-1.4364E-05" izz="0.0024659" />
    </inertial>
    <visual>
      <origin xyz="0 0 0" rpy="0 0 0" />
      <geometry>
        <mesh filename="package://aubo_description/meshes/aubo_i5/visual/base_link.DAE" />
      </geometry>
      <material name="">
        <color rgba="1 1 1 1" />
      </material>
    </visual>
    <collision>
      <origin xyz="0 0 0" rpy="0 0 0" />
      <geometry>
        <mesh filename="package://aubo_description/meshes/aubo_i5/collision/base_link.STL" />
      </geometry>
    </collision>
  </link>

  <!--/////////////////////////////// SHOULDER_LINK ////////////////////////////////////-->
  <link name="shoulder_Link">
    <inertial>
      <xacro:I5_Shoulder_Inertia />
    </inertial>
    <visual>
      <origin xyz="0 0 0" rpy="0 0 0" />
      <geometry>
        <mesh filename="package://aubo_description/meshes/aubo_i5/visual/shoulder_Link.DAE" />
      </geometry>
      <material name="">
        <color rgba="1 1 1 1" />
      </material>
    </visual>
    <collision>
      <origin xyz="0 0 0" rpy="0 0 0" />
      <geometry>
        <mesh filename="package://aubo_description/meshes/aubo_i5/collision/shoulder_Link.STL" />
      </geometry>
    </collision>
  </link>


  <!--/////////////////////////////// SHOULDER_JOINT ////////////////////////////////////-->
  <joint name="shoulder_joint" type="revolute">
    <origin xyz="0 0 0.122" rpy="0 0 3.1416" />
    <parent link="base_link" />
    <child link="shoulder_Link" />
    <axis xyz="0 0 1" />
    <limit lower="-3.04" upper="3.04" effort="300" velocity="100" />
  </joint>


  <!--/////////////////////////////// UPPERARM_LINK ////////////////////////////////////-->
  <link name="upperArm_Link">
    <inertial>
      <xacro:I5_UpperArm_Inertia />
    </inertial>
    <visual>
      <origin xyz="0 0 0" rpy="0 0 0" />
      <geometry>
        <mesh filename="package://aubo_description/meshes/aubo_i5/visual/upperArm_Link.DAE" />
      </geometry>
      <material name="">
        <color rgba="1 1 1 1" />
      </material>
    </visual>
    <collision>
      <origin xyz="0 0 0" rpy="0 0 0" />
      <geometry>
        <mesh filename="package://aubo_description/meshes/aubo_i5/collision/upperArm_Link.STL" />
      </geometry>
    </collision>
  </link>

  <!--/////////////////////////////// UPPERARM_JOINT ////////////////////////////////////-->
  <joint name="upperArm_joint" type="revolute">
    <origin xyz="0 0.1215 0" rpy="-1.5708 -1.5708 0" />
    <parent link="shoulder_Link" />
    <child link="upperArm_Link" />
    <axis xyz="0 0 1" />
    <limit lower="-3.04" upper="3.04" effort="300" velocity="100" />
  </joint>


  <!--/////////////////////////////// FOREARM_LINK ////////////////////////////////////-->
  <link name="foreArm_Link">
    <inertial>
      <xacro:I5_ForeArm_Inertia />
    </inertial>
    <visual>
      <origin xyz="0 0 0" rpy="0 0 0" />
      <geometry>
        <mesh filename="package://aubo_description/meshes/aubo_i5/visual/foreArm_Link.DAE" />
      </geometry>
      <material name="">
        <color rgba="1 1 1 1" />
      </material>
    </visual>
    <collision>
      <origin xyz="0 0 0" rpy="0 0 0" />
      <geometry>
        <mesh filename="package://aubo_description/meshes/aubo_i5/collision/foreArm_Link.STL" />
      </geometry>
    </collision>
  </link>


  <!--/////////////////////////////// FOREARM_JOINT ////////////////////////////////////-->
  <joint name="foreArm_joint" type="revolute">
    <origin xyz="0.408 0 0" rpy="-3.1416 -5.1632E-18 -5.459E-16" />
    <parent link="upperArm_Link" />
    <child link="foreArm_Link" />
    <axis xyz="0 0 1" />
    <limit lower="-3.04" upper="3.04" effort="300" velocity="100" />
  </joint>


  <!--/////////////////////////////// WRIST1_LINK ////////////////////////////////////-->
  <link name="wrist1_Link">
    <inertial>
      <xacro:I5_Wrist1_Inertia />
    </inertial>
    <visual>
      <origin xyz="0 0 0" rpy="0 0 0" />
      <geometry>
        <mesh filename="package://aubo_description/meshes/aubo_i5/visual/wrist1_Link.DAE" />
      </geometry>
      <material name="">
        <color rgba="1 1 1 1" />
      </material>
    </visual>
    <collision>
      <origin xyz="0 0 0" rpy="0 0 0" />
      <geometry>
        <mesh filename="package://aubo_description/meshes/aubo_i5/collision/wrist1_Link.STL" />
      </geometry>
    </collision>
  </link>


  <!--/////////////////////////////// WRIST1_JOINT ////////////////////////////////////-->
  <joint name="wrist1_joint" type="revolute">
    <origin xyz="0.376 0 0" rpy="3.1416 -1.8323E-15 1.5708" />
    <parent link="foreArm_Link" />
    <child link="wrist1_Link" />
    <axis xyz="0 0 1" />
    <limit lower="-3.04" upper="3.04" effort="300" velocity="100" />
  </joint>

  <!--/////////////////////////////// WRIST2_LINK ////////////////////////////////////-->
  <link name="wrist2_Link">
    <inertial>
      <xacro:I5_Wrist2_Inertia />
    </inertial>
    <visual>
      <origin xyz="0 0 0" rpy="0 0 0" />
      <geometry>
        <mesh filename="package://aubo_description/meshes/aubo_i5/visual/wrist2_Link.DAE" />
      </geometry>
      <material name="">
        <color rgba="1 1 1 1" />
      </material>
    </visual>
    <collision>
      <origin xyz="0 0 0" rpy="0 0 0" />
      <geometry>
        <mesh filename="package://aubo_description/meshes/aubo_i5/collision/wrist2_Link.STL" />
      </geometry>
    </collision>
  </link>

  <!--/////////////////////////////// WRIST2_JOINT ////////////////////////////////////-->
  <joint name="wrist2_joint" type="revolute">
    <origin xyz="0 0.1025 0" rpy="-1.5708 -1.8709E-15 -1.6653E-16" />
    <parent link="wrist1_Link" />
    <child link="wrist2_Link" />
    <axis xyz="0 0 1" />
    <limit lower="-3.04" upper="3.04" effort="300" velocity="100" />
  </joint>

  <!--/////////////////////////////// WRIST3_LINK ////////////////////////////////////-->
  <link name="wrist3_Link">
    <inertial>
      <xacro:I5_Wrist3_Inertia />
    </inertial>
    <visual>
      <origin xyz="0 0 0" rpy="0 0 0" />
      <geometry>
        <mesh filename="package://aubo_description/meshes/aubo_i5/visual/wrist3_Link.DAE" />
      </geometry>
      <material name="">
        <color rgba="1 1 1 1" />
      </material>
    </visual>
    <collision>
      <origin xyz="0 0 0" rpy="0 0 0" />
      <geometry>
        <mesh filename="package://aubo_description/meshes/aubo_i5/collision/wrist3_Link.STL" />
      </geometry>
    </collision>
  </link>

  <!--/////////////////////////////// WRIST3_JOINT ////////////////////////////////////-->
  <joint name="wrist3_joint" type="revolute">
    <origin xyz="0 -0.094 0" rpy="1.5708 0 1.7907E-15" />
    <parent link="wrist2_Link" />
    <child link="wrist3_Link" />
    <axis xyz="0 0 1" />
    <limit lower="-3.04" upper="3.04" effort="300" velocity="100" />
  </joint>



  <!-- /////////////////////////////////   i5 pedestal_Link   ////////////////////////////////////// -->
  <link name="pedestal_Link">
    <visual>
      <geometry>
        <mesh filename="package://aubo_description/meshes/aubo_i5/collision/pedestal.STL" />
      </geometry>
    </visual>
  </link>

  <joint name="pedestal_joint" type="fixed">
    <parent link="pedestal_Link"/>
    <child link="base_link"/>
    <origin xyz="0.0 0.0 0.402" rpy="0.0 0.0 0.0" />
  </joint>


 <!-- /////////////////////////////////   world   ////////////////////////////////////// -->
  <link name="world" />

  <joint name="world_joint" type="fixed">
    <parent link="world" />
    <child link ="pedestal_Link" />
    <origin xyz="0.0 0.0 0.1" rpy="0.0 0.0 0.0" />
  </joint>


  <!-- /////////////////////////////////   gazebo color   ////////////////////////////////////// -->
  <gazebo reference="pedestal_Link">
     <material>Gazebo/Grey</material>
  </gazebo>

  <!--////////////////////////////////// Transmissions for ROS Control //////////////////////////-->

<xacro:macro name="aubo_arm_transmission" params="joint_name">
     <transmission name="${joint_name}_trans">
       <type>transmission_interface/SimpleTransmission</type>
       <joint name="${joint_name}">
         <!--<hardwareInterface>hardware_interface/PositionJointInterface</hardwareInterface>-->
         <hardwareInterface>hardware_interface/PositionJointInterface</hardwareInterface>
       </joint>
       <actuator name="${joint_name}_motor">
         <mechanicalReduction>1</mechanicalReduction>
       </actuator>
     </transmission>
 </xacro:macro>


  <xacro:aubo_arm_transmission joint_name="shoulder_joint"/>
  <xacro:aubo_arm_transmission joint_name="upperArm_joint"/>
  <xacro:aubo_arm_transmission joint_name="foreArm_joint"/>
  <xacro:aubo_arm_transmission joint_name="wrist1_joint"/>
  <xacro:aubo_arm_transmission joint_name="wrist2_joint"/>
  <xacro:aubo_arm_transmission joint_name="wrist3_joint"/>




  <!-- ros_control plugin -->
  <gazebo>
      <plugin name="gazebo_ros_control" filename="libgazebo_ros_control.so">
          <robotNamespace>/aubo_i5</robotNamespace>
      </plugin>
  </gazebo>



</robot>
