<?xml version="1.0"?>
<robot name="aubo_i5L_robot">

  <link name="base_link">
    <inertial>
      <origin rpy="0 0 0" xyz="-5.5723E-10 -0.00053181 0.016438"/>
      <mass value="0.5499"/>
      <inertia ixx="0.0011098" ixy="1.3184E-11" ixz="3.3523E-12" iyy="0.0011174" iyz="-1.2673E-05" izz="0.002061"/>
    </inertial>
    <visual>
      <origin rpy="0 0 0" xyz="0 0 0"/>
      <geometry>
        <mesh filename="package://aubo_description/meshes/aubo_i5l/base_link.STL"/>
      </geometry>
     <material name="black">
        <color rgba="0.25098 0.25098 0.25098"/>
      </material>
    </visual>
    <collision>
      <origin rpy="0 0 0" xyz="0 0 0"/>
      <geometry>
        <mesh filename="package://aubo_description/meshes/aubo_i5l/base_link.STL"/>
      </geometry>
    </collision>
  </link>
  <link name="shoulder_Link">
    <inertial>
      <origin rpy="0 0 0" xyz="1.8797E-06 0.0063705 -0.014752"/>
      <mass value="1.4505"/>
      <inertia ixx="0.0032429" ixy="5.3132E-08" ixz="-1.3896E-08" iyy="0.0031222" iyz="-0.00024889" izz="0.0027718"/>
    </inertial>
    <visual>
      <origin rpy="0 0 0" xyz="0 0 0"/>
      <geometry>
        <mesh filename="package://aubo_description/meshes/aubo_i5l/shoulder_Link.STL"/>
      </geometry>
       <material name="orange">
        <color rgba="1 0.65098 0 1"/>
      </material>
    </visual>
    <collision>
      <origin rpy="0 0 0" xyz="0 0 0"/>
      <geometry>
        <mesh filename="package://aubo_description/meshes/aubo_i5l/shoulder_Link.STL"/>
      </geometry>
    </collision>
  </link>
  <joint name="shoulder_joint" type="revolute">
    <origin rpy="0 0 3.1416" xyz="0 0 0.122"/>
    <parent link="base_link"/>
    <child link="shoulder_Link"/>
    <axis xyz="0 0 1"/>
    <limit effort="0" lower="-3.04" upper="3.04" velocity="0"/>
  </joint>
  <link name="upperArm_Link">
    <inertial>
      <origin rpy="0 0 0" xyz="0.304 1.1022E-06 0.0069544"/>
      <mass value="3.552"/>
      <inertia ixx="0.0075968" ixy="-3.9847E-07" ixz="1.2349E-09" iyy="0.28172" iyz="3.2578E-07" izz="0.28066"/>
    </inertial>
    <visual>
      <origin rpy="0 0 0" xyz="0 0 0"/>
      <geometry>
        <mesh filename="package://aubo_description/meshes/aubo_i5l/upperArm_Link.STL"/>
      </geometry>
       <material name="orange">
        <color rgba="1 0.65098 0 1"/>
      </material>
    </visual>
    <collision>
      <origin rpy="0 0 0" xyz="0 0 0"/>
      <geometry>
        <mesh filename="package://aubo_description/meshes/aubo_i5l/upperArm_Link.STL"/>
      </geometry>
    </collision>
  </link>
  <joint name="upperArm_joint" type="revolute">
    <origin rpy="-1.5708 -1.5708 0" xyz="0 0.1215 0"/>
    <parent link="shoulder_Link"/>
    <child link="upperArm_Link"/>
    <axis xyz="0 0 1"/>
    <limit effort="0" lower="-3.04" upper="3.04" velocity="0"/>
  </joint>
  <link name="foreArm_Link">
    <inertial>
      <origin rpy="0 0 0" xyz="0.47998 -3.2016E-06 0.096041"/>
      <mass value="0.90769"/>
      <inertia ixx="0.0010698" ixy="-3.7747E-07" ixz="0.00094801" iyy="0.034604" iyz="2.1581E-07" izz="0.034439"/>
    </inertial>
    <visual>
      <origin rpy="0 0 0" xyz="0 0 0"/>
      <geometry>
        <mesh filename="package://aubo_description/meshes/aubo_i5l/foreArm_Link.STL"/>
      </geometry>
        <material name="orange">
        <color rgba="1 0.65098 0 1"/>
      </material>
    </visual>
    <collision>
      <origin rpy="0 0 0" xyz="0 0 0"/>
      <geometry>
        <mesh filename="package://aubo_description/meshes/aubo_i5l/foreArm_Link.STL"/>
      </geometry>
    </collision>
  </link>
  <joint name="foreArm_joint" type="revolute">
    <origin rpy="-3.1416 0 0" xyz="0.608 0 0"/>
    <parent link="upperArm_Link"/>
    <child link="foreArm_Link"/>
    <axis xyz="0 0 1"/>
    <limit effort="0" lower="-3.04" upper="3.04" velocity="0"/>
  </joint>
  <link name="wrist1_Link">
    <inertial>
      <origin rpy="0 0 0" xyz="4.9891E-07 0.013119 -0.0045696"/>
      <mass value="0.44686"/>
      <inertia ixx="0.00048851" ixy="-3.823E-09" ixz="8.3651E-09" iyy="0.00036127" iyz="-3.9646E-05" izz="0.00046417"/>
    </inertial>
    <visual>
      <origin rpy="0 0 0" xyz="0 0 0"/>
      <geometry>
        <mesh filename="package://aubo_description/meshes/aubo_i5l/wrist1_Link.STL"/>
      </geometry>
     <material name="orange">
        <color rgba="1 0.65098 0 1"/>
      </material>
    </visual>
    <collision>
      <origin rpy="0 0 0" xyz="0 0 0"/>
      <geometry>
        <mesh filename="package://aubo_description/meshes/aubo_i5l/wrist1_Link.STL"/>
      </geometry>
    </collision>
  </link>
  <joint name="wrist1_joint" type="revolute">
    <origin rpy="3.1416 -1.1102E-16 1.5708" xyz="0.6395 0 0"/>
    <parent link="foreArm_Link"/>
    <child link="wrist1_Link"/>
    <axis xyz="0 0 1"/>
    <limit effort="0" lower="-3.04" upper="3.04" velocity="0"/>
  </joint>
  <link name="wrist2_Link">
    <inertial>
      <origin rpy="0 0 0" xyz="-4.9891E-07 -0.013119 -0.0045696"/>
      <mass value="0.44686"/>
      <inertia ixx="0.00048851" ixy="-3.823E-09" ixz="-8.3651E-09" iyy="0.00036127" iyz="3.9646E-05" izz="0.00046417"/>
    </inertial>
    <visual>
      <origin rpy="0 0 0" xyz="0 0 0"/>
      <geometry>
        <mesh filename="package://aubo_description/meshes/aubo_i5l/wrist2_Link.STL"/>
      </geometry>
      <material name="orange">
        <color rgba="1 0.65098 0 1"/>
      </material>
    </visual>
    <collision>
      <origin rpy="0 0 0" xyz="0 0 0"/>
      <geometry>
        <mesh filename="package://aubo_description/meshes/aubo_i5l/wrist2_Link.STL"/>
      </geometry>
    </collision>
  </link>
  <joint name="wrist2_joint" type="revolute">
    <origin rpy="-1.5708 0 -1.6653E-16" xyz="0 0.1025 0"/>
    <parent link="wrist1_Link"/>
    <child link="wrist2_Link"/>
    <axis xyz="0 0 1"/>
    <limit effort="0" lower="-3.04" upper="3.04" velocity="0"/>
  </joint>
  <link name="wrist3_Link">
    <inertial>
      <origin rpy="0 0 0" xyz="2.2512E-08 0.00029937 -0.018058"/>
      <mass value="0.14035"/>
      <inertia ixx="6.1524E-05" ixy="-1.0358E-10" ixz="3.0206E-11" iyy="5.9833E-05" iyz="4.033E-07" izz="9.5362E-05"/>
    </inertial>
    <visual>
      <origin rpy="0 0 0" xyz="0 0 0"/>
      <geometry>
        <mesh filename="package://aubo_description/meshes/aubo_i5l/wrist3_Link.STL"/>
      </geometry>
      <material name="black">
        <color rgba="0.25098 0.25098 0.25098"/>
      </material>
    </visual>
    <collision>
      <origin rpy="0 0 0" xyz="0 0 0"/>
      <geometry>
        <mesh filename="package://aubo_description/meshes/aubo_i5l/wrist3_Link.STL"/>
      </geometry>
    </collision>
  </link>
  <joint name="wrist3_joint" type="revolute">
    <origin rpy="1.5708 -1.6653E-16 0" xyz="0 -0.094 0"/>
    <parent link="wrist2_Link"/>
    <child link="wrist3_Link"/>
    <axis xyz="0 0 1"/>
    <limit effort="0" lower="-3.04" upper="3.04" velocity="0"/>
  </joint>
  <link name="w2_Link">
    <inertial>
      <origin rpy="0 0 0" xyz="-3.646E-06 0.047634 0.0038418"/>
      <mass value="0.021594"/>
      <inertia ixx="1.4206E-05" ixy="3.911E-10" ixz="2.2226E-09" iyy="2.3397E-05" iyz="1.7259E-06" izz="1.4321E-05"/>
    </inertial>
    <visual>
      <origin rpy="0 0 0" xyz="0 0 0"/>
      <geometry>
        <mesh filename="package://aubo_description/meshes/aubo_i5l/w2_Link.STL"/>
      </geometry>
      <material name="black">
        <color rgba="0.25098 0.25098 0.25098"/>
      </material>
    </visual>
    <collision>
      <origin rpy="0 0 0" xyz="0 0 0"/>
      <geometry>
        <mesh filename="package://aubo_description/meshes/aubo_i5l/w2_Link.STL"/>
      </geometry>
    </collision>
  </link>
  <joint name="w2_joint" type="fixed">
    <origin rpy="0 0 0" xyz="0 0 0"/>
    <parent link="wrist2_Link"/>
    <child link="w2_Link"/>
    <axis xyz="0 0 0"/>
  </joint>
  <link name="w1_Link">
    <inertial>
      <origin rpy="0 0 0" xyz="3.646E-06 -0.047634 0.0038418"/>
      <mass value="0.021594"/>
      <inertia ixx="1.4206E-05" ixy="3.911E-10" ixz="-2.2226E-09" iyy="2.3397E-05" iyz="-1.7259E-06" izz="1.4321E-05"/>
    </inertial>
    <visual>
      <origin rpy="0 0 0" xyz="0 0 0"/>
      <geometry>
        <mesh filename="package://aubo_description/meshes/aubo_i5l/w1_Link.STL"/>
      </geometry>
      <material name="black">
        <color rgba="0.25098 0.25098 0.25098"/>
      </material>
    </visual>
    <collision>
      <origin rpy="0 0 0" xyz="0 0 0"/>
      <geometry>
        <mesh filename="package://aubo_description/meshes/aubo_i5l/w1_Link.STL"/>
      </geometry>
    </collision>
  </link>
  <joint name="w1_joint" type="fixed">
    <origin rpy="0 0 0" xyz="0 0 0"/>
    <parent link="wrist1_Link"/>
    <child link="w1_Link"/>
    <axis xyz="0 0 0"/>
  </joint>
  <link name="u_Link">
    <inertial>
      <origin rpy="0 0 0" xyz="0.64334 -3.6405E-06 0.15013"/>
      <mass value="0.021594"/>
      <inertia ixx="1.4321E-05" ixy="2.224E-09" ixz="1.7259E-06" iyy="1.4206E-05" iyz="3.9014E-10" izz="2.3397E-05"/>
    </inertial>
    <visual>
      <origin rpy="0 0 0" xyz="0 0 0"/>
      <geometry>
        <mesh filename="package://aubo_description/meshes/aubo_i5l/u_Link.STL"/>
      </geometry>
      <material name="black">
        <color rgba="0.25098 0.25098 0.25098"/>
      </material>
    </visual>
    <collision>
      <origin rpy="0 0 0" xyz="0 0 0"/>
      <geometry>
        <mesh filename="package://aubo_description/meshes/aubo_i5l/u_Link.STL"/>
      </geometry>
    </collision>
  </link>
  <joint name="u_joint" type="fixed">
    <origin rpy="3.2724E-33 0 0" xyz="0 0 0"/>
    <parent link="foreArm_Link"/>
    <child link="u_Link"/>
    <axis xyz="0 0 0"/>
  </joint>
  <link name="f1_Link">
    <inertial>
      <origin rpy="0 0 0" xyz="0.30397 -0.00049907 0.08414"/>
      <mass value="0.22341"/>
      <inertia ixx="0.00030759" ixy="3.3453E-05" ixz="0.00029518" iyy="0.021935" iyz="-3.0461E-06" izz="0.022161"/>
    </inertial>
    <visual>
      <origin rpy="0 0 0" xyz="0 0 0"/>
      <geometry>
        <mesh filename="package://aubo_description/meshes/aubo_i5l/f1_Link.STL"/>
      </geometry>
      <material name="black">
        <color rgba="0.25098 0.25098 0.25098"/>
      </material>
    </visual>
    <collision>
      <origin rpy="0 0 0" xyz="0 0 0"/>
      <geometry>
        <mesh filename="package://aubo_description/meshes/aubo_i5l/f1_Link.STL"/>
      </geometry>
    </collision>
  </link>
  <joint name="f1_joint" type="fixed">
    <origin rpy="0 0 0" xyz="0 0 0"/>
    <parent link="upperArm_Link"/>
    <child link="f1_Link"/>
    <axis xyz="0 0 0"/>
  </joint>
  <link name="s_Link">
    <inertial>
      <origin rpy="0 0 0" xyz="6.0938E-06 -0.0072488 0.058805"/>
      <mass value="0.11171"/>
      <inertia ixx="0.00014572" ixy="-3.291E-09" ixz="-8.2879E-09" iyy="0.00015181" iyz="-1.8811E-05" izz="0.00026098"/>
    </inertial>
    <visual>
      <origin rpy="0 0 0" xyz="0 0 0"/>
      <geometry>
        <mesh filename="package://aubo_description/meshes/aubo_i5l/s_Link.STL"/>
      </geometry>
      <material name="black">
        <color rgba="0.25098 0.25098 0.25098"/>
      </material>
    </visual>
    <collision>
      <origin rpy="0 0 0" xyz="0 0 0"/>
      <geometry>
        <mesh filename="package://aubo_description/meshes/aubo_i5l/s_Link.STL"/>
      </geometry>
    </collision>
  </link>
  <joint name="s_joint" type="fixed">
    <origin rpy="0 0 0" xyz="0 0 0"/>
    <parent link="shoulder_Link"/>
    <child link="s_Link"/>
    <axis xyz="0 0 0"/>
  </joint>

  <link name="world" />
  <joint name="world_joint" type="fixed">
    <parent link="world" />
    <child link = "base_link" />
    <origin xyz="0.0 0.0 0.0" rpy="0.0 0.0 0.0" />
  </joint>

</robot>
