<?xml version="1.0"?>
<robot  name="aubo_move_arm">

 <link name="base_link">
    <inertial>
      <origin xyz="0 0.00054789 0.02299" rpy="0 0 0" />
      <mass value="1.2345" />
      <inertia ixx="0.0029215" ixy="0.0" ixz="0.0" iyy="0.0028546" iyz="0.0" izz="0.0051176" />
    </inertial>
    <visual>
      <origin xyz="0 0 0" rpy="0 0 0" />
      <geometry>
        <mesh filename="package://aubo_description/meshes/aubo_i10/base_link.DAE" />
      </geometry>
      <material name="">
        <color rgba="1 1 1 1" />
      </material>
    </visual>
    <collision>
      <origin xyz="0 0 0" rpy="0 0 0" />
      <geometry>
        <mesh filename="package://aubo_description/meshes/aubo_i10/base_link.STL" />
      </geometry>
    </collision>
  </link>

<!-- shoulder_Link -->

  <link name="shoulder_Link">
    <inertial>
      <origin xyz="0.00029287 0.14173 0.54281" rpy="0 0 0" />
      <mass value="10.994" />
      <inertia ixx="2.2088" ixy="-0.00043922" ixz="-0.0025417" iyy="2.1473" iyz="-0.049088" izz="0.07998" />
    </inertial>
    <visual>
      <origin xyz="0 0 0" rpy="0 0 0" />
      <geometry>
        <mesh
          filename="package://aubo_description/meshes/aubo_i10/shoulder_Link.DAE" />
      </geometry>
      <material name="">
        <color rgba="0.89804 0.91765 0.92941 1" />
      </material>
    </visual>
    <collision>
      <origin xyz="0 0 0" rpy="0 0 0" />
      <geometry>
        <mesh filename="package://aubo_description/meshes/aubo_i10/shoulder_Link.STL" />
      </geometry>
    </collision>
  </link>

<!-- shoulder_joint -->

  <joint name="shoulder_joint" type="revolute">
    <origin xyz="0 0 0.1632" rpy="0.0 0.0 3.1416" />
    <parent link="base_link" />
    <child link="shoulder_Link" />
    <axis xyz="0 0 1" />
    <limit lower="-3.05" upper="3.05" effort="0" velocity="0" />
  </joint>

<!-- upperArm_Link -->

  <link name="upperArm_Link">
    <inertial>
      <origin xyz="0.31908 0.0 -0.0042956" rpy="0 0 0" />
      <mass value="5.3139" />
      <inertia ixx="0.0095171" ixy="0.0" ixz="0.0" iyy="0.11411" iyz="0.0" izz="0.11411" />
    </inertial>
    <visual>
      <origin xyz="0 0 0" rpy="0 0 0" />
      <geometry>
        <mesh filename="package://aubo_description/meshes/aubo_i10/upperArm_Link.DAE" />
      </geometry>
      <material name="">
        <color rgba="0.89804 0.91765 0.92941 1" />
      </material>
    </visual>
    <collision>
      <origin xyz="0 0 0" rpy="0 0 0" />
      <geometry>
        <mesh filename="package://aubo_description/meshes/aubo_i10/upperArm_Link.STL" />
      </geometry>
    </collision>
  </link>

<!-- upperArm_Joint -->

  <joint name="upperArm_joint" type="revolute">
    <origin xyz="0 0.2013 0" rpy="-1.5708 -1.5708 0" />
    <parent link="shoulder_Link" />
    <child link="upperArm_Link" />
    <axis xyz="0 0 1" />
    <limit lower="-3.05" upper="3.05" effort="0" velocity="0" />
  </joint>

<!-- foreArm_Link -->

  <link name="foreArm_Link">
    <inertial>
      <origin xyz="0.24431 0.0 0.12549" rpy="0 0 0" />
      <mass value="3.1022" />
      <inertia ixx="0.0027288" ixy="0.0" ixz="-0.0018082" iyy="0.097825" iyz="0.0" izz="0.097866" />
    </inertial>
    <visual>
      <origin xyz="0 0 0" rpy="0 0 0" />
      <geometry>
        <mesh filename="package://aubo_description/meshes/aubo_i10/foreArm_Link.DAE" />
      </geometry>
      <material name="">
        <color rgba="1 1 1 1" />
      </material>
    </visual>
    <collision>
      <origin xyz="0 0 0" rpy="0 0 0" />
      <geometry>
        <mesh filename="package://aubo_description/meshes/aubo_i10/foreArm_Link.STL" />
      </geometry>
    </collision>
  </link>

<!-- foreArm_Joint -->

  <joint name="foreArm_joint" type="revolute">
    <origin xyz="0.647 0 0" rpy="-3.1416 0 0" />
    <parent link="upperArm_Link" />
    <child link="foreArm_Link" />
    <axis xyz="0 0 1" />
    <limit lower="-3.05" upper="3.05" effort="0" velocity="0" />
  </joint>

<!-- wrist1_Link -->

  <link name="wrist1_Link">
    <inertial>
      <origin xyz="0.0 0.00026581 -0.0027894" rpy="0 0 0" />
      <mass value="0.57981" />
      <inertia ixx="0.00088336" ixy="0.0" ixz="0.0" iyy="0.00046118" iyz="0.0" izz="0.00085336" />
    </inertial>
    <visual>
      <origin xyz="0 0 0" rpy="0 0 0" />
      <geometry>
        <mesh filename="package://aubo_description/meshes/aubo_i10/wrist1_Link.DAE" />
      </geometry>
      <material name="">
        <color rgba="1 1 1 1" />
      </material>
    </visual>
    <collision>
      <origin xyz="0 0 0" rpy="0 0 0" />
      <geometry>
        <mesh filename="package://aubo_description/meshes/aubo_i10/wrist1_Link.STL" />
      </geometry>
    </collision>
  </link>

<!-- wrist1_Joint -->

  <joint name="wrist1_joint" type="revolute">
    <origin xyz="0.6005 0 0" rpy="-3.1416 0.0 1.5708" />
    <parent link="foreArm_Link" />
    <child link="wrist1_Link" />
    <axis xyz="0 0 1" />
    <limit lower="-3.05" upper="3.05" effort="0" velocity="0" />
  </joint>

<!-- wrist2_Link -->

  <link name="wrist2_Link">
    <inertial>
      <origin xyz="0.0 -0.00026581 -0.0027894" rpy="0 0 0" />
      <mass value="0.57981" />
      <inertia ixx="0.00088336" ixy="0.0" ixz="0.0" iyy="0.00046118" iyz="0.0" izz="0.00085336" />
    </inertial>
    <visual>
      <origin xyz="0 0 0" rpy="0 0 0" />
      <geometry>
        <mesh filename="package://aubo_description/meshes/aubo_i10/wrist2_Link.DAE" />
      </geometry>
      <material name="">
        <color rgba="1 1 1 1" />
      </material>
    </visual>
    <collision>
      <origin xyz="0 0 0" rpy="0 0 0" />
      <geometry>
        <mesh filename="package://aubo_description/meshes/aubo_i10/wrist2_Link.STL" />
      </geometry>
    </collision>
  </link>

<!-- wrist2_Joint -->

  <joint name="wrist2_joint" type="revolute">
    <origin xyz="0 0.1025 0" rpy="-1.5708 0.0 0.0" />
    <parent link="wrist1_Link" />
    <child link="wrist2_Link" />
    <axis xyz="0 0 1" />
    <limit lower="-3.05" upper="3.05" effort="0" velocity="0" />
  </joint>

<!-- wrist3_Link -->

  <link name="wrist3_Link">
    <inertial>
      <origin xyz="0.0 0.00023722 -0.018629" rpy="0 0 0" />
      <mass value="0.13669" />
      <inertia ixx="0.0" ixy="0.0" ixz="0.0" iyy="0.0" iyz="0.0" izz="0.0" />
    </inertial>
    <visual>
      <origin xyz="0 0 0" rpy="0 0 0" />
      <geometry>
        <mesh filename="package://aubo_description/meshes/aubo_i10/wrist3_Link.DAE" />
      </geometry>
      <material name="">
        <color rgba="1 1 1 1" />
      </material>
    </visual>
    <collision>
      <origin xyz="0 0 0" rpy="0 0 0" />
      <geometry>
        <mesh filename="package://aubo_description/meshes/aubo_i10/wrist3_Link.STL" />
      </geometry>
    </collision>
  </link>

<!-- wrist3_Joint -->

  <joint name="wrist3_joint" type="revolute">
    <origin xyz="0 -0.094 0" rpy="1.5708 0 0.0" />
    <parent link="wrist2_Link" />
    <child link="wrist3_Link" />
    <axis xyz="0 0 1" />
    <limit lower="-3.05" upper="3.05" effort="0" velocity="0" />
  </joint>

  <link name="arm_mount">
    <inertial>
      <origin xyz="0 -0.455 0.341222591098982" rpy="0 0 0" />
      <mass value="2.51971475607568" />
      <inertia ixx="0.19472488053588" ixy="0.0" ixz="0.0" iyy="0.0473782628423338" iyz="0.0180682441158683" izz="0.204967153671127" />
    </inertial>
    <visual>
      <origin xyz="0 0 0" rpy="0 0 0" />
     <geometry>
        <mesh filename="package://aubo_description/meshes/GreyOrange/arm_mount.STL" />
      </geometry>
      <material
        name="">
        <color rgba="0.5 0.5 0.5 1" />
      </material>
    </visual>
    <collision>
      <origin xyz="0 0 0" rpy="0 0 0" />
      <geometry>
        <mesh filename="package://aubo_description/meshes/GreyOrange/arm_mount.STL" />
      </geometry>
    </collision>
  </link>

  <joint name="arm_mount_joint" type="prismatic">
    <origin  xyz="0 -0.455 0.391"  rpy="-1.5708 0.0 0.0" />
    <parent link="base_frame" />
    <child  link="arm_mount" />
    <axis   xyz="0 0 -1" />
    <limit lower="-0.8" upper="0.8" effort="0" velocity="0" />
  </joint>

  <joint  name="fixed_joint"type="fixed">
    <origin      xyz="0 -0.914999999999998 0.289816257482792"      rpy="1.57079632679495 0 0" />
    <parent      link="arm_mount" />
    <child       link="base_link" />
    <axis      xyz="0 0 0" />
  </joint>

  <link name="base_frame">
    <inertial>
      <origin xyz="-0.0003981 -0.099766 0.25931" rpy="0 0 0" />
      <mass value="14.309" />
      <inertia ixx="3.8007" ixy="0.003083" ixz="0.00027976" iyy="0.44559" iyz="0.054147" izz="3.8034" />
    </inertial>
    <visual>
      <origin xyz="0 0 0" rpy="0 0 0" />
      <geometry>
        <mesh filename="package://aubo_description/meshes/GreyOrange/base_frame.STL" />
      </geometry>
      <material name="">
        <color rgba="0.5 0.6 0.8 1" />
      </material>
    </visual>
    <collision>
      <origin xyz="0 0 0" rpy="0 0 0" />
      <geometry>
        <mesh filename="package://aubo_description/meshes/GreyOrange/base_frame.STL" />
      </geometry>
    </collision>
  </link>

  <link name="world" />
  <joint name="world_joint" type="fixed">
    <parent link="world" />
    <child link = "base_frame" />
    <origin xyz="0.0 0.0 0.0" rpy="0.0 0.0 0.0" />
  </joint>
</robot>
