<?xml version="1.0" ?>
<!-- =================================================================================== -->
<!-- |    This document was autogenerated by xacro from aubo.URDF           | -->
<!-- |    EDITING THIS FILE BY HAND IS NOT RECOMMENDED                                 | -->
<!-- =================================================================================== -->
<!-- =================================================================================== -->
<!-- |    This document was autogenerated by xacro from ur3_robot.urdf.xacro           | -->
<!-- |    EDITING THIS FILE BY HAND IS NOT RECOMMENDED                                 | -->
<!-- =================================================================================== -->
<robot name="OUR-i5-l.SLDASM" xmlns:xacro="http://ros.org/wiki/xacro">
  <!-- common stuff -->
  <gazebo>
    <plugin filename="libgazebo_ros_control.so" name="ros_control">
      <!--robotNamespace>/</robotNamespace-->
      <!--robotSimType>gazebo_ros_control/DefaultRobotHWSim</robotSimType-->
    </plugin>
    <!--
    <plugin name="gazebo_ros_power_monitor_controller" filename="libgazebo_ros_power_monitor.so">
      <alwaysOn>true</alwaysOn>
      <updateRate>1.0</updateRate>
      <timeout>5</timeout>
      <powerStateTopic>power_state</powerStateTopic>
      <powerStateRate>10.0</powerStateRate>
      <fullChargeCapacity>87.78</fullChargeCapacity>     
      <dischargeRate>-474</dischargeRate>
      <chargeRate>525</chargeRate>
      <dischargeVoltage>15.52</dischargeVoltage>
      <chargeVoltage>16.41</chargeVoltage>
    </plugin>
-->
  </gazebo>
  <link name="base_link">
    <inertial>
      <origin rpy="0 0 0" xyz="-5.57229196054101E-10 -0.000531813617543912 0.0164378415129375"/>
      <mass value="0.54989774205518"/>
      <inertia ixx="0.00110977600313612" ixy="-1.31843875171894E-11" ixz="-3.35232059640074E-12" iyy="0.00111737671268686" iyz="1.26733632666035E-05" izz="0.00206099319078327"/>
    </inertial>
    <visual>
      <origin rpy="0 0 0" xyz="0 0 0"/>
      <geometry>
        <mesh filename="package://aubo_description/meshesL/base_link.STL"/>
      </geometry>
      <material name="">
        <color rgba="1 1 1 1"/>
      </material>
    </visual>
    <collision>
      <origin rpy="0 0 0" xyz="0 0 0"/>
      <geometry>
        <mesh filename="package://aubo_description/meshesL/base_link.STL"/>
      </geometry>
    </collision>
  </link>
  <link name="Link1">
    <inertial>
      <origin rpy="0 0 0" xyz="1.87970023452043E-06 0.00637047267468252 -0.0147515179284357"/>
      <mass value="1.45053403461403"/>
      <inertia ixx="0.00324288954575581" ixy="-5.31319685687332E-08" ixz="1.38960804502907E-08" iyy="0.00312223359067137" iyz="0.000248893917288594" izz="0.00277178877858537"/>
    </inertial>
    <visual>
      <origin rpy="0 0 0" xyz="0 0 0"/>
      <geometry>
        <mesh filename="package://aubo_description/meshesL/Link1.STL"/>
      </geometry>
      <material name="">
        <color rgba="1 1 1 1"/>
      </material>
    </visual>
    <collision>
      <origin rpy="0 0 0" xyz="0 0 0"/>
      <geometry>
        <mesh filename="package://aubo_description/meshesL/Link1.STL"/>
      </geometry>
    </collision>
  </link>
  <joint name="joint1" type="revolute">
    <origin rpy="0 0 3.1416" xyz="0 0 0.122"/>
    <parent link="base_link"/>
    <child link="Link1"/>
    <axis xyz="0 0 1"/>
    <limit effort="0" velocity="0"/>
  </joint>
  <link name="Link2">
    <inertial>
      <origin rpy="0 0 0" xyz="0.294414822773256 -0.000297715046961625 0.0092727688992784"/>
      <mass value="3.62734833678504"/>
      <inertia ixx="0.00836781674359783" ixy="-2.12314509571195E-07" ixz="-0.00277341023380772" iyy="0.291248558996861" iyz="-1.06924266578437E-05" izz="0.289595579823037"/>
    </inertial>
    <visual>
      <origin rpy="0 0 0" xyz="0 0 0"/>
      <geometry>
        <mesh filename="package://aubo_description/meshesL/Link2.STL"/>
      </geometry>
      <material name="">
        <color rgba="1 1 1 1"/>
      </material>
    </visual>
    <collision>
      <origin rpy="0 0 0" xyz="0 0 0"/>
      <geometry>
        <mesh filename="package://aubo_description/meshesL/Link2.STL"/>
      </geometry>
    </collision>
  </link>
  <joint name="joint2" type="revolute">
    <origin rpy="1.5708 -1.5708 0" xyz="0 0.1215 0"/>
    <parent link="Link1"/>
    <child link="Link2"/>
    <axis xyz="0 0 1"/>
    <limit effort="0" velocity="0"/>
  </joint>
  <link name="Link3">
    <inertial>
      <origin rpy="0 0 0" xyz="0.483780016296186 -3.21178511585151E-06 0.0972983393857147"/>
      <mass value="0.929288667169107"/>
      <inertia ixx="0.00114582622653691" ixy="3.73738448739536E-07" ixz="-0.000763357222064429" iyy="0.0352430303964066" iyz="-2.167035254705E-07" izz="0.0350253550918067"/>
    </inertial>
    <visual>
      <origin rpy="0 0 0" xyz="0 0 0"/>
      <geometry>
        <mesh filename="package://aubo_description/meshesL/Link3.STL"/>
      </geometry>
      <material name="">
        <color rgba="1 1 1 1"/>
      </material>
    </visual>
    <collision>
      <origin rpy="0 0 0" xyz="0 0 0"/>
      <geometry>
        <mesh filename="package://aubo_description/meshesL/Link3.STL"/>
      </geometry>
    </collision>
  </link>
  <joint name="joint3" type="revolute">
    <origin rpy="3.1416 0 0" xyz="0.608 0 0"/>
    <parent link="Link2"/>
    <child link="Link3"/>
    <axis xyz="0 0 -1"/>
    <limit effort="0" velocity="0"/>
  </joint>
  <link name="Link4">
    <inertial>
      <origin rpy="0 0 0" xyz="6.4398415824315E-07 0.0103188036816546 -0.00418186970904275"/>
      <mass value="0.468450173746542"/>
      <inertia ixx="0.000580201565613755" ixy="-5.06600869832481E-10" ixz="-5.59725150068685E-09" iyy="0.000386123089058949" iyz="3.08455499414554E-05" izz="0.000554524434066764"/>
    </inertial>
    <visual>
      <origin rpy="0 0 0" xyz="0 0 0"/>
      <geometry>
        <mesh filename="package://aubo_description/meshesL/Link4.STL"/>
      </geometry>
      <material name="">
        <color rgba="1 1 1 1"/>
      </material>
    </visual>
    <collision>
      <origin rpy="0 0 0" xyz="0 0 0"/>
      <geometry>
        <mesh filename="package://aubo_description/meshesL/Link4.STL"/>
      </geometry>
    </collision>
  </link>
  <joint name="joint4" type="revolute">
    <origin rpy="3.1416 -1.1102E-16 1.5708" xyz="0.6395 0 0"/>
    <parent link="Link3"/>
    <child link="Link4"/>
    <axis xyz="0 0 -1"/>
    <limit effort="0" velocity="0"/>
  </joint>
  <link name="Link5">
    <inertial>
      <origin rpy="0 0 0" xyz="-6.4398427785668E-07 -0.0103188036811817 -0.00418186970907297"/>
      <mass value="0.468450173749648"/>
      <inertia ixx="0.000580201565628262" ixy="-5.06605018312111E-10" ixz="5.59725181726394E-09" iyy="0.000386123089060139" iyz="-3.08455499425923E-05" izz="0.000554524434082312"/>
    </inertial>
    <visual>
      <origin rpy="0 0 0" xyz="0 0 0"/>
      <geometry>
        <mesh filename="package://aubo_description/meshesL/Link5.STL"/>
      </geometry>
      <material name="">
        <color rgba="1 1 1 1"/>
      </material>
    </visual>
    <collision>
      <origin rpy="0 0 0" xyz="0 0 0"/>
      <geometry>
        <mesh filename="package://aubo_description/meshesL/Link5.STL"/>
      </geometry>
    </collision>
  </link>
  <joint name="joint5" type="revolute">
    <origin rpy="-1.5708 0 -1.6653E-16" xyz="0 0.1025 0"/>
    <parent link="Link4"/>
    <child link="Link5"/>
    <axis xyz="0 0 -1"/>
    <limit effort="0" velocity="0"/>
  </joint>
  <link name="LinkEE">
    <inertial>
      <origin rpy="0 0 0" xyz="2.25117342442483E-08 0.000299371413911453 -0.018057646821789"/>
      <mass value="0.140347016703156"/>
      <inertia ixx="6.1524416860916E-05" ixy="1.03582618179579E-10" ixz="-3.02062741962272E-11" iyy="5.98329195473529E-05" iyz="-4.03300019297283E-07" izz="9.53619803852634E-05"/>
    </inertial>
    <visual>
      <origin rpy="0 0 0" xyz="0 0 0"/>
      <geometry>
        <mesh filename="package://aubo_description/meshesL/LinkEE.STL"/>
      </geometry>
      <material name="">
        <color rgba="1 1 1 1"/>
      </material>
    </visual>
    <collision>
      <origin rpy="0 0 0" xyz="0 0 0"/>
      <geometry>
        <mesh filename="package://aubo_description/meshesL/LinkEE.STL"/>
      </geometry>
    </collision>
  </link>
  <joint name="joint6" type="revolute">
    <origin rpy="1.5708 -1.6653E-16 0" xyz="0 -0.094 0"/>
    <parent link="Link5"/>
    <child link="LinkEE"/>
    <axis xyz="0 0 -1"/>
    <limit effort="0" velocity="0"/>
  </joint>
  <link name="base"/>
  <joint name="base_link-base_fixed_joint" type="fixed">
    <!-- NOTE: this rotation is only needed as long as base_link itself is
                 not corrected wrt the real robot (ie: rotated over 180
                 degrees)
      -->
    <origin rpy="0 0 -3.14159265" xyz="0 0 0"/>
    <parent link="base_link"/>
    <child link="base"/>
  </joint>
  <!-- Frame coincident with all-zeros TCP on UR controller -->
  <link name="tool0"/>
  <joint name="wrist_3_link-tool0_fixed_joint" type="fixed">
    <origin rpy="-1.570796325 0 0" xyz="0 0.0819 0"/>
    <parent link="LinkEE"/>
    <child link="tool0"/>
  </joint>
  <link name="world"/>
  <joint name="world_joint" type="fixed">
    <parent link="world"/>
    <child link="base_link"/>
    <origin rpy="0.0 0.0 0.0" xyz="0.0 0.0 0.0"/>
  </joint>
</robot>
